#VRML_SIM R2019a utf8
WorldInfo {
}
Viewpoint {
  orientation 0.006337117842889904 -0.999975037556644 0.003124932164629862 0.9162698037081772
  position -0.8934584285191028 0.1929111866033708 0.9135247342844658
}
TexturedBackground {
}
TexturedBackgroundLight {
}
Floor {
}
Robot {
  translation 0.007333816523873885 0.07104358393452252 5.6401599898617365e-05
  rotation -0.0015926891415161497 0.04813881964508368 0.9988393851788568 -0.06415777885812704
  children [
    DEF GR_BODY Group {
      children [
        DEF ROBOT_BODY Shape {
          appearance PBRAppearance {
            baseColor 0.9294117647058824 0.8313725490196079 0
          }
          geometry DEF G_BODY Box {
            size 0.25 0.07 0.1
          }
        }
        Transform {
          translation 0.11 -0.05 0
          children [
            Shape {
              appearance PBRAppearance {
                baseColor 0.12549019607843137 0.2901960784313726 0.5294117647058824
                roughness 1
                metalness 0
              }
              geometry Sphere {
                radius 0.015
              }
            }
          ]
        }
      ]
    }
    DEF WHEEL1_JOINT HingeJoint {
      jointParameters HingeJointParameters {
        position 1.0690272063390396
        axis 0 0 1
        anchor -0.05 0 0.06
      }
      device [
        PositionSensor {
          name "encoder1"
          resolution 1
        }
        RotationalMotor {
          name "motor_right"
          maxVelocity 8.33
          maxTorque 0.49
        }
      ]
      endPoint DEF WHEEL1 Solid {
        translation -0.05000489137162684 9.063405721303895e-06 0.06000161495516592
        rotation 0.7667606948640197 0.45391600128882015 0.45391441989169434 1.833311903914309
        children [
          DEF SH_WHEEL Shape {
            appearance DEF A_WHEEL PBRAppearance {
              baseColor 0 0 0
              roughness 1
              metalness 0
            }
            geometry DEF G_WHEEL Cylinder {
              height 0.02
              radius 0.075
            }
          }
        ]
        boundingObject USE G_WHEEL
        physics Physics {
          density 500
        }
      }
    }
    DEF WHEEL2 HingeJoint {
      jointParameters HingeJointParameters {
        position 0.057129380576761826
        axis 0 0 1
        anchor -0.05 0 -0.06
      }
      device [
        RotationalMotor {
          name "motor_left"
          maxVelocity 8.33
          maxTorque 0.49
        }
      ]
      endPoint Solid {
        translation -0.05 0 -0.06
        rotation -0.9991846160335142 -0.02854916433660914 0.028549050730987707 1.5716160225814382
        children [
          Shape {
            appearance USE A_WHEEL
            geometry USE G_WHEEL
          }
        ]
        name "solid(1)"
        boundingObject USE G_WHEEL
        physics Physics {
        }
      }
    }
    DistanceSensor {
      translation 0.125 0 0
      rotation 1 0 0 0.6544996938995746
      children [
        Shape {
          appearance PBRAppearance {
            baseColor 0.807843137254902 0.3607843137254902 0
          }
          geometry Box {
            size 0.02 0.01 0.01
          }
        }
      ]
      name "distance_sensor"
      lookupTable [
        0 0 0
        0.03 0 0
        5 256 0
      ]
      resolution 1
    }
  ]
  boundingObject USE GR_BODY
  physics Physics {
    density 500
  }
  controller "u2_exam"
}
Solid {
  translation 1.2200000083632054 0.1993658818637652 8.363205112598483e-09
  rotation 0.7071067484123694 4.2641384424649964e-08 -0.707106813960723 -5.531933342873362e-10
  children [
    Shape {
      appearance PBRAppearance {
        baseColor 0.12549019607843137 0.2901960784313726 0.5294117647058824
      }
      geometry DEF G_BOX Box {
        size 0.2 0.4 0.2
      }
    }
  ]
  boundingObject USE G_BOX
  physics Physics {
    density 101
  }
}
